<?xml version="1.0" ?>
<robot name="agv" xmlns:xacro="http://ros.org/wiki/xacro">
  <xacro:include filename="$(find agv)/urdf/common_properties.xacro"/>
  <xacro:include filename="$(find agv)/urdf/agv.gazebo.xacro"/>

  <link name="base_footprint"/>

  <joint name="base_joint" type="fixed">
    <parent link="base_footprint"/>
    <child link="base_link"/>
    <origin xyz="0.0 0.0 0.010" rpy="0 0 0"/>
  </joint>

      <link name="base_link">
        <inertial>
            <mass value="0.1"/> <!--0.1-->
            <origin xyz="0 0 0.02"/>
            <inertia ixx="0.482916666667e-1" ixy="0" ixz="0" iyy="0.482916666667e-1" iyz="0" izz="0.05625"/>
        </inertial>
        <visual>
            <origin rpy="0 0 0" xyz="0 0 0.01"/>
            <geometry>
                <box size="0.4 0.28 0.02" />
            </geometry>
            <material name="White"/>
        </visual>
        <collision>
            <origin rpy="0 0 0 " xyz="0 0 0.01"/>
            <geometry>
                <box size="0.4 0.28 0.02" />
            </geometry>
        </collision>
    </link>



  <!-- <joint name="base_joint" type="fixed">
    <parent link="base_footprint"/>
    <child link="base_link"/>
    <origin xyz="0.0 0.0 0.010" rpy="0 0 0"/>
  </joint>
 -->



    <!--Caster Left Wheel  -->
    <link name="caster_left_link">
        <visual>
            <origin rpy="1.57079632679 0 0" xyz="0 0.02 0"/>
            <geometry>
                <sphere radius="0.025"/>
            </geometry>
            <material name="Black"/>
        </visual>
        <collision>
            <geometry>
                <sphere radius="0.025"/>
            </geometry>
            <origin rpy="1.57079632679 0 0" xyz="0 0.02 0"/>
        </collision>
        <inertial>
            <mass value="0.05"/>
            <origin xyz="0 0 0"/>
            <inertia ixx="0.01" ixy="0.0" ixz="0.0" iyy="0.01" iyz="0.0" izz="0.01"/>
        </inertial>
    </link>
    <joint name="caster_left_joint" type="fixed">
        <parent link="base_link"/>
        <child link="caster_left_link"/>
        <origin rpy="-1.57079632679 0 0" xyz="0.115 0.1 0.007"/>
    </joint>




    <!--Caster Right Wheel  -->
    <link name="caster_right_link">
        <visual>
            <origin rpy="1.57079632679 0 0" xyz="0.02 0.02 0 "/>
            <geometry>
                <sphere radius="0.025"/>
            </geometry>
            <material name="Black"/>
        </visual>
        <collision>
            <geometry>
                <sphere radius="0.025"/>
            </geometry>
            <origin rpy="1.57079632679 0 0" xyz="0 0.02 0 "/>
        </collision>
        <inertial>
            <mass value="0.05"/>
            <origin xyz="0 0 0"/>
            <inertia ixx="0.01" ixy="0.0" ixz="0.0" iyy="0.01" iyz="0.0" izz="0.01"/>
        </inertial>
    </link>


    <joint name="caster_right_joint" type="fixed">
        <parent link="base_link"/>
        <child link="caster_right_link"/>
                 <origin rpy="-1.57079632679 0 0" xyz="0.115 -0.1 0.007"/>
        <axis rpy="0 0 0" xyz="0 1 0"/>  
    </joint>


  <joint name="wheel_left_joint" type="continuous">
    <parent link="base_link"/>
    <child link="wheel_left_link"/>
    <origin xyz="-0.1 0.15 0.0" rpy="0 0 0"/>
    <axis xyz="0 1 0"/>
  </joint>

  <link name="wheel_left_link">
            <visual>
            <origin rpy="1.57079632679 0  0 " xyz="0 0 0"/>
            <geometry>
                <cylinder length="0.02" radius="0.04"/>
            </geometry>
            <material name="DarkGray"/>
            </visual>
        <collision>
            <origin rpy="1.57079632679 0 0 " xyz="0 0 0"/>
            <geometry>
                <cylinder length="0.02" radius="0.04"/>
            </geometry>
        </collision>
        <inertial>
            <mass value="0.25"/>
            <origin xyz="0 0 0"/>
            <inertia ixx="0.00108333333333" ixy="0" ixz="0" iyy="0.00108333333333" iyz="0" izz="0.002"/>
        </inertial>
  </link>

  <joint name="wheel_right_joint" type="continuous">
    <parent link="base_link"/>
    <child link="wheel_right_link"/>
    <origin xyz="-0.1 -0.15 0.0" rpy="0 0 0"/>
    <axis xyz="0 1 0"/>
  </joint>

  <link name="wheel_right_link">
            <visual>
            <origin rpy="1.57079632679 0  0 " xyz="0 0 0"/>
            <geometry>
                <cylinder length="0.02" radius="0.04"/>
            </geometry>
            <material name="DarkGray"/>
        </visual>
        <collision>
            <origin rpy="1.57079632679 0 0 " xyz="0 0 0"/>
            <geometry>
                <cylinder length="0.02" radius="0.04"/>
            </geometry>
        </collision>
            <inertial>
            <mass value="0.25"/>
            <origin xyz="0 0 0"/>
            <inertia ixx="0.00108333333333" ixy="0" ixz="0" iyy="0.00108333333333" iyz="0" izz="0.002"/>
        </inertial>
  </link>

  
  <joint name="scan_joint" type="fixed">
    <parent link="base_link"/>
    <child link="base_scan"/>
    <origin xyz="-0.032 0 0.172" rpy="0 0 0"/>
  </joint>

  <link name="base_scan">
    <visual>
      <origin xyz="0 0 0.0" rpy="0 0 0"/>
      <geometry>
        <mesh filename="package://turtlebot3_description/meshes/sensors/lds.stl" scale="0.001 0.001 0.001"/>
      </geometry>
      <material name="dark"/>
    </visual>

    <collision>
      <origin xyz="0.015 0 -0.0065" rpy="0 0 0"/>
      <geometry>
        <cylinder length="0.0315" radius="0.055"/>
      </geometry>
    </collision>

    <inertial>
      <mass value="0.114" />
      <origin xyz="0 0 0" />
      <inertia ixx="0.001" ixy="0.0" ixz="0.0"
               iyy="0.001" iyz="0.0"
               izz="0.001" />
    </inertial>
  </link>

</robot>




